2019-04-04 21:27:23.779 [error] <0.373.0> CRASH REPORT Process <0.373.0> with 0 neighbours exited with reason: #{'__exception__' => true,'__struct__' => 'Elixir.ArgumentError',message => <<"supervisors expect each child to be one of the following:\n\n  * a module\n  * a {module, arg} tuple\n  * a child specification as a map with at least the :id and :start fields\n  * or a tuple with 6 elements generated by Supervisor.Spec (deprecated)\n\nGot: {Apr.AmqEventService, [%{topic: \"commerce\"}], [id: :commerce]}\n">>} in 'Elixir.Supervisor':init_child/1 line 646 in application_master:init/4 line 138
2019-04-04 21:40:33.278 [error] <0.355.0> Supervisor 'Elixir.Apr.Supervisor' had child commerce started with 'Elixir.Apr.AmqEventService':start_link(#{topic => <<"commerce">>}) at <0.502.0> exit with reason normal in context child_terminated
2019-04-04 21:42:50.375 [error] <0.518.0> ** Task <0.518.0> terminating
** Started from <0.517.0>
** When function  == #Fun<Elixir.Apr.AmqEventService.0.51857244>
**      arguments == []
** Reason for termination == 
** {#{'__exception__' => true,'__struct__' => 'Elixir.Postgrex.Error',connection_id => 55118,message => nil,postgres => #{code => undefined_table,file => <<"parse_relation.c">>,line => <<"1180">>,message => <<"relation \"events\" does not exist">>,pg_code => <<"42P01">>,position => <<"13">>,routine => <<"parserOpenTable">>,severity => <<"ERROR">>,unknown => <<"ERROR">>},query => <<"INSERT INTO \"events\" (\"payload\",\"routing_key\",\"topic\",\"inserted_at\",\"updated_at\") VALUES ($1,$2,$3,$4,$5) RETURNING \"id\"">>},[{'Elixir.Ecto.Adapters.SQL',raise_sql_call_error,1,[{file,"lib/ecto/adapters/sql.ex"},{line,605}]},{'Elixir.Ecto.Repo.Schema',apply,4,[{file,"lib/ecto/repo/schema.ex"},{line,649}]},{'Elixir.Ecto.Repo.Schema','-do_insert/4-fun-1-',15,[{file,"lib/ecto/repo/schema.ex"},{line,262}]},{'Elixir.Task.Supervised',invoke_mfa,2,[{file,"lib/task/supervised.ex"},{line,90}]},{'Elixir.Task.Supervised',reply,5,[{file,"lib/task/supervised.ex"},{line,35}]},{proc_lib,init_p_do_apply,3,[{file,"proc_lib.erl"},{line,249}]}]}
2019-04-04 21:42:50.387 [error] <0.518.0> CRASH REPORT Process <0.518.0> with 0 neighbours crashed with reason: #{'__exception__' => true,'__struct__' => 'Elixir.Postgrex.Error',connection_id => 55118,message => nil,postgres => #{code => undefined_table,file => <<"parse_relation.c">>,line => <<"1180">>,message => <<"relation \"events\" does not exist">>,pg_code => <<"42P01">>,position => <<"13">>,routine => <<"parserOpenTable">>,severity => <<"ERROR">>,unknown => <<"ERROR">>},query => <<"INSERT INTO \"events\" (\"payload\",\"routing_key\",\"topic\",\"inserted_at\",\"updated_at\") VALUES ($1,$2,$3,$4,$5) RETURNING ...">>} in 'Elixir.Ecto.Adapters.SQL':raise_sql_call_error/1 line 605
2019-04-05 15:34:33.708 [error] <0.552.0>@Elixir.Phoenix.LiveView.Channel:handle_info:51 gen_server <0.552.0> terminated with reason: call to undefined function 'Elixir.AprWeb.OrderDashboardLive':handle_event/3 from 'Elixir.Phoenix.LiveView.Channel':handle_info/2 line 51
2019-04-05 15:34:33.757 [error] <0.552.0>@Elixir.AprWeb.OrderDashboardLive:handle_event CRASH REPORT Process <0.552.0> with 0 neighbours crashed with reason: call to undefined function 'Elixir.AprWeb.OrderDashboardLive':handle_event(<<"filter">>, #{<<"mode">> => <<"order">>}, #{'__struct__' => 'Elixir.Phoenix.LiveView.Socket',assigns => #{events => [#{'__meta__' => #{...},...},...]},...})
2019-04-05 15:34:33.758 [error] <0.395.0>@Elixir.AprWeb.OrderDashboardLive:handle_event Supervisor {<0.395.0>,'Elixir.Supervisor.Default'} had child 'Elixir.Phoenix.Channel.Server' started with {'Elixir.Phoenix.Channel.Server',start_link,undefined} at <0.552.0> exit with reason call to undefined function 'Elixir.AprWeb.OrderDashboardLive':handle_event(<<"filter">>, #{<<"mode">> => <<"order">>}, #{'__struct__' => 'Elixir.Phoenix.LiveView.Socket',assigns => #{events => [#{'__meta__' => #{...},...},...]},...}) in context child_terminated
2019-04-05 15:34:35.980 [error] <0.560.0>@Elixir.Phoenix.LiveView.Channel:handle_info:51 gen_server <0.560.0> terminated with reason: call to undefined function 'Elixir.AprWeb.OrderDashboardLive':handle_event/3 from 'Elixir.Phoenix.LiveView.Channel':handle_info/2 line 51
2019-04-05 15:34:35.991 [error] <0.560.0>@Elixir.AprWeb.OrderDashboardLive:handle_event CRASH REPORT Process <0.560.0> with 0 neighbours crashed with reason: call to undefined function 'Elixir.AprWeb.OrderDashboardLive':handle_event(<<"filter">>, #{<<"mode">> => <<"offer">>}, #{'__struct__' => 'Elixir.Phoenix.LiveView.Socket',assigns => #{events => [#{'__meta__' => #{...},...},...]},...})
2019-04-05 15:34:35.991 [error] <0.393.0>@Elixir.AprWeb.OrderDashboardLive:handle_event Supervisor {<0.393.0>,'Elixir.Supervisor.Default'} had child 'Elixir.Phoenix.Channel.Server' started with {'Elixir.Phoenix.Channel.Server',start_link,undefined} at <0.560.0> exit with reason call to undefined function 'Elixir.AprWeb.OrderDashboardLive':handle_event(<<"filter">>, #{<<"mode">> => <<"offer">>}, #{'__struct__' => 'Elixir.Phoenix.LiveView.Socket',assigns => #{events => [#{'__meta__' => #{...},...},...]},...}) in context child_terminated
